Traceback (most recent call last):
  File "/usr/local/lib/python3.9/site-packages/jupyter_cache/executors/utils.py", line 51, in single_nb_execution
    executenb(
  File "/usr/local/lib/python3.9/site-packages/nbclient/client.py", line 1087, in execute
    return NotebookClient(nb=nb, resources=resources, km=km, **kwargs).execute()
  File "/usr/local/lib/python3.9/site-packages/nbclient/util.py", line 74, in wrapped
    return just_run(coro(*args, **kwargs))
  File "/usr/local/lib/python3.9/site-packages/nbclient/util.py", line 53, in just_run
    return loop.run_until_complete(coro)
  File "/usr/local/Cellar/python@3.9/3.9.9/Frameworks/Python.framework/Versions/3.9/lib/python3.9/asyncio/base_events.py", line 642, in run_until_complete
    return future.result()
  File "/usr/local/lib/python3.9/site-packages/nbclient/client.py", line 540, in async_execute
    await self.async_execute_cell(
  File "/usr/local/lib/python3.9/site-packages/nbclient/client.py", line 832, in async_execute_cell
    self._check_raise_for_error(cell, exec_reply)
  File "/usr/local/lib/python3.9/site-packages/nbclient/client.py", line 740, in _check_raise_for_error
    raise CellExecutionError.from_cell_and_msg(cell, exec_reply['content'])
nbclient.exceptions.CellExecutionError: An error occurred while executing the following cell:
------------------
x = 1
y = 4
z = y/(1-x)
------------------

[0;31m---------------------------------------------------------------------------[0m
[0;31mZeroDivisionError[0m                         Traceback (most recent call last)
[0;32m<ipython-input-11-d93e730d8440>[0m in [0;36m<module>[0;34m[0m
[1;32m      1[0m [0mx[0m [0;34m=[0m [0;36m1[0m[0;34m[0m[0;34m[0m[0m
[1;32m      2[0m [0my[0m [0;34m=[0m [0;36m4[0m[0;34m[0m[0;34m[0m[0m
[0;32m----> 3[0;31m [0mz[0m [0;34m=[0m [0my[0m[0;34m/[0m[0;34m([0m[0;36m1[0m[0;34m-[0m[0mx[0m[0;34m)[0m[0;34m[0m[0;34m[0m[0m
[0m
[0;31mZeroDivisionError[0m: division by zero
ZeroDivisionError: division by zero

